Workbook
Name Slicer_Age_Bracket: #N/A
Name Slicer_Gender: #N/A
Name Slicer_Marital_Status: #N/A

Sheet updated sheet
A1: First Name | B1: Last Name | C1: Full Name | D1: Gender | E1: Age | F1: Age Bracket | G1: Occupation | H1: Salary | I1: Marital Status | J1: No. of Children
A2: Jacob | B2: Robinson | C2: Jacob Robinson | D2: Male | E2: 58 | F2: =IF(E2>50,"Old",IF(E2>=31,"Middle Age",IF(E2<31,"Young","Invalid"))) -> Old | G2: Lawyer | H2: 6779 | I2: Married | J2: 2
A3: Grace | B3: Taylor | C3: Grace Taylor | D3: Female | E3: 36 | F3: =IF(E3>50,"Old",IF(E3>=31,"Middle Age",IF(E3<31,"Young","Invalid"))) -> Middle Age | G3: Insurer | H3: 4466 | I3: Married | J3: 1
A4: Charlie | B4: Wilson | C4: Charlie Wilson | D4: Male | E4: 58 | F4: =IF(E4>50,"Old",IF(E4>=31,"Middle Age",IF(E4<31,"Young","Invalid"))) -> Old | G4: Aeroplane Pilot | H4: 5786 | I4: Single | J4: 0
A5: Vanessa | B5: Farrell | C5: Vanessa Farrell | D5: Female | E5: 23 | F5: =IF(E5>50,"Old",IF(E5>=31,"Middle Age",IF(E5<31,"Young","Invalid"))) -> Young | G5: Lawyer | H5: 3403 | I5: Married | J5: 2
A6: Fenton | B6: Harrison | C6: Fenton Harrison | D6: Male | E6: 21 | F6: =IF(E6>50,"Old",IF(E6>=31,"Middle Age",IF(E6<31,"Young","Invalid"))) -> Young | G6: Architect | H6: 693 | I6: Married | J6: 0
A7: Lucas | B7: Brooks | C7: Lucas Brooks | D7: Male | E7: 38 | F7: =IF(E7>50,"Old",IF(E7>=31,"Middle Age",IF(E7<31,"Young","Invalid"))) -> Middle Age | G7: Auditor | H7: 3029 | I7: Single | J7: 1
A8: Belinda | B8: Spencer | C8: Belinda Spencer | D8: Female | E8: 24 | F8: =IF(E8>50,"Old",IF(E8>=31,"Middle Age",IF(E8<31,"Young","Invalid"))) -> Young | G8: Dancer | H8: 8927 | I8: Married | J8: 5
A9: Ashton | B9: Farrell | C9: Ashton Farrell | D9: Male | E9: 30 | F9: =IF(E9>50,"Old",IF(E9>=31,"Middle Age",IF(E9<31,"Young","Invalid"))) -> Young | G9: Cook | H9: 916 | I9: Married | J9: 1
A10: Kellan | B10: Williams | C10: Kellan Williams | D10: Male | E10: 38 | F10: =IF(E10>50,"Old",IF(E10>=31,"Middle Age",IF(E10<31,"Young","Invalid"))) -> Middle Age | G10: Police Officer | H10: 8337 | I10: Married | J10: 4
A11: Tyler | B11: Davis | C11: Tyler Davis | D11: Male | E11: 60 | F11: =IF(E11>50,"Old",IF(E11>=31,"Middle Age",IF(E11<31,"Young","Invalid"))) -> Old | G11: Dancer | H11: 2705 | I11: Married | J11: 1
A12: Alina | B12: Russell | C12: Alina Russell | D12: Female | E12: 51 | F12: =IF(E12>50,"Old",IF(E12>=31,"Middle Age",IF(E12<31,"Young","Invalid"))) -> Old | G12: Engineer | H12: 8411 | I12: Single | J12: 0
A13: Tiana | B13: Wright | C13: Tiana Wright | D13: Female | E13: 59 | F13: =IF(E13>50,"Old",IF(E13>=31,"Middle Age",IF(E13<31,"Young","Invalid"))) -> Old | G13: Composer | H13: 8087 | I13: Single | J13: 4
... A1001: Dexter | B1001: Williams | C1001: Dexter Williams | D1001: Male | E1001: 58 | F1001: =IF(E1001>50,"Old",IF(E1001>=31,"Middle Age",IF(E1001<31,"Young","Invalid"))) -> Old | G1001: Insurer | H1001: 7075 | I1001: Single | J1001: 0

Sheet pivot
B5: Column Labels
B6: Female | C6: Male | D6: Average Total
A7: Average of Salary | B7: 5225.7819 | C7: 5376.9066 | D7: 5303.46
B19: Column Labels
B20: Middle Age | C20: Old | D20: Young | E20: Average Total
A21: Average of Salary | B21: 5194.485 | C21: 5209.3109 | D21: 5553.1463 | E21: 5303.46
B36: Column Labels
B37: Mechanic | C37: Aeroplane Pilot | D37: Accountant | E37: Firefighter | F37: Police Officer | G37: Dancer | H37: Meteorologist | I37: Chef | J37: Archeologist | K37: Journalist | L37: Average Salary
A38: Average of Salary | B38: 6884.5 | C38: 6691.1667 | D38: 6615 | E38: 6578.6 | F38: 6554.8667 | G38: 6206.7143 | H38: 6166.3158 | I38: 6125.5 | J38: 6117.3 | K38: 6035.1429 | L38: 6367.7193
A57: Row Labels | B57: Sum of No. of Children
A58: Married | B58: 1175
A59: Single | B59: 1272
A60: Grand Total | B60: 2447

Sheet Dashboard
A1: SURVEY DASHBOARD

Sheet Observations
A1: 20 interesting observations from the data
A5: 1 | C5: Unique Occupations: There are 53 unique occupations in the dataset.
A6: 2 | C6: Gender Distribution: The gender distribution is 514 males and 486 females.
A7: 3 | C7: Age Statistics: The average age is 39.5 years, with a minimum age of 18 and a maximum age of 60.
A8: 4 | C8: Most Common Age Bracket: The most common age bracket is "Middle Age," with 468 individuals.
A9: 5 | C9: Average Salary by Gender: The average salary for females is $5,226, while for males, it's $5,377.
A10: 6 | C10: Highest Paying Occupation: The occupation with the highest average salary is "Mechanic," with an average salary of $6,885.
A11: 7 | C11: Marital Status: 48.7% of the individuals are married.
A12: 8 | C12: Individuals with Children: 830 individuals have at least one child.
A13: 9 | C13: Most Common Occupation: The most common occupation is "Insurer."
A14: 10 | C14: Highest Salary: The highest salary in the dataset is $10,000.
A15: 11 | C15: Lowest Salary: The lowest salary is $520.
A16: 12 | C16: Gender with Highest Average Number of Children: Males have the highest average number of children.
... A24: 20 | C24: Gender with Highest Salary: Males have the highest average salary. ​

Sheet Assignment
A2: 1. Steps involved in an analytical project:
A3: 1. Problem Definition
A4: 2. Data Collection
A5: 3. Data Preparation
A6: 4. Exploratory Data Analysis (EDA)
A7: 5. Modeling/Analysis
A8: 6. Interpretation and Insights
A9: 7. Communication of Results
A10: 8. Implementation
A11: 9. Documentation
A12: 10. Review and Iteration
A14: 2. Technical tools I have used for data analysis and presentation:
... A28: I did a project in the final year of my master’s whose name was “Prediction and analysis of heart attack”. Compared to all my projects till now, it was a difficult project for me.

Sheet Filter_function
B2: Gender | D2: First Name | E2: Last Name | F2: Full Name | G2: Gender | H2: Age | I2: Age Bracket | J2: Occupation | K2: Salary | L2: Marital Status | M2: No. of Children
B3: Male | D3: {=_xlfn._xlws.FILTER(Sheet1!$A:$J,(Sheet1!$D:$D=Filter_function!$B$3)*(Sheet1!$H:$H>5000)*(Sheet1!J:J>=2))} -> Jacob | E3: Robinson | F3: Jacob Robinson | G3: Male | H3: 58 | I3: Old | J3: Lawyer | K3: 6779 | L3: Married | M3: 2
D4: Kellan | E4: Williams | F4: Kellan Williams | G4: Male | H4: 38 | I4: Middle Age | J4: Police Officer | K4: 8337 | L4: Married | M4: 4
D5: Richard | E5: Richards | F5: Richard Richards | G5: Male | H5: 56 | I5: Old | J5: Engineer | K5: 6229 | L5: Single | M5: 2
D6: Alan | E6: Allen | F6: Alan Allen | G6: Male | H6: 57 | I6: Old | J6: Singer | K6: 5461 | L6: Single | M6: 2
D7: Sawyer | E7: Carter | F7: Sawyer Carter | G7: Male | H7: 26 | I7: Young | J7: Medic | K7: 9039 | L7: Married | M7: 4
D8: Frederick | E8: Johnson | F8: Frederick Johnson | G8: Male | H8: 49 | I8: Middle Age | J8: Programmer | K8: 5998 | L8: Married | M8: 2
D9: Roman | E9: Campbell | F9: Roman Campbell | G9: Male | H9: 23 | I9: Young | J9: Aeroplane Pilot | K9: 9654 | L9: Single | M9: 2
D10: Fenton | E10: Kelly | F10: Fenton Kelly | G10: Male | H10: 46 | I10: Middle Age | J10: Architect | K10: 8547 | L10: Married | M10: 4
D11: Jack | E11: Riley | F11: Jack Riley | G11: Male | H11: 59 | I11: Old | J11: Driver | K11: 6452 | L11: Single | M11: 2
D12: Jared | E12: Carter | F12: Jared Carter | G12: Male | H12: 34 | I12: Middle Age | J12: Meteorologist | K12: 8791 | L12: Married | M12: 2
D13: Kellan | E13: Campbell | F13: Kellan Campbell | G13: Male | H13: 21 | I13: Young | J13: Police Officer | K13: 8410 | L13: Single | M13: 5
D14: Maximilian | E14: Ryan | F14: Maximilian Ryan | G14: Male | H14: 24 | I14: Young | J14: Florist | K14: 5072 | L14: Single | M14: 2
D15: Eric | E15: Perkins | F15: Eric Perkins | G15: Male | H15: 40 | I15: Middle Age | J15: Hairdresser | K15: 7506 | L15: Married | M15: 4
... D178: Roman | E178: Martin | F178: Roman Martin | G178: Male | H178: 26 | I178: Young | J178: Pharmacist | K178: 6532 | L178: Single | M178: 4

Sheet index match
C1: Marital Status
C2: Single | D2: Full Name | E2: Last Name | F2: No. of Children | G2: Age Bracket | J2: Married | K2: Full Name | L2: Last Name | M2: No. of Children | N2: Age Bracket
D3: {=_xlfn._xlws.FILTER(Sheet1!C:C,Sheet1!I:I='index match'!C2)} -> Charlie Wilson | E3: =INDEX(Sheet1!$A:$J,MATCH('index match'!$D3,Sheet1!$C:$C,0),MATCH('index match'!E$2,Sheet1!$1:$1,0)) -> Wilson | F3: =INDEX(Sheet1!$A:$J,MATCH('index match'!$D3,Sheet1!$C:$C,0),MATCH('index match'!F$2,Sheet1!$1:$1,0)) -> 0 | G3: =INDEX(Sheet1!$A:$J,MATCH('index match'!$D3,Sheet1!$C:$C,0),MATCH('index match'!G$2,Sheet1!$1:$1,0)) -> Old | K3: {=_xlfn._xlws.FILTER(Sheet1!C:C,Sheet1!I:I='index match'!J2)} -> Jacob Robinson | L3: =INDEX(Sheet1!$A:$J,MATCH('index match'!$K3,Sheet1!$C:$C,0),MATCH('index match'!L$2,Sheet1!$A$1:$J$1,0)) -> Robinson | M3: =INDEX(Sheet1!$A:$J,MATCH('index match'!$K3,Sheet1!$C:$C,0),MATCH('index match'!M$2,Sheet1!$A$1:$J$1,0)) -> 2 | N3: =INDEX(Sheet1!$A:$J,MATCH('index match'!$K3,Sheet1!$C:$C,0),MATCH('index match'!N$2,Sheet1!$A$1:$J$1,0)) -> Old
D4: Lucas Brooks | E4: =INDEX(Sheet1!$A:$J,MATCH('index match'!$D4,Sheet1!$C:$C,0),MATCH('index match'!E$2,Sheet1!$1:$1,0)) -> Brooks | F4: =INDEX(Sheet1!$A:$J,MATCH('index match'!$D4,Sheet1!$C:$C,0),MATCH('index match'!F$2,Sheet1!$1:$1,0)) -> 1 | G4: =INDEX(Sheet1!$A:$J,MATCH('index match'!$D4,Sheet1!$C:$C,0),MATCH('index match'!G$2,Sheet1!$1:$1,0)) -> Middle Age | K4: Grace Taylor | L4: =INDEX(Sheet1!$A:$J,MATCH('index match'!$K4,Sheet1!$C:$C,0),MATCH('index match'!L$2,Sheet1!$A$1:$J$1,0)) -> Taylor | M4: =INDEX(Sheet1!$A:$J,MATCH('index match'!$K4,Sheet1!$C:$C,0),MATCH('index match'!M$2,Sheet1!$A$1:$J$1,0)) -> 1 | N4: =INDEX(Sheet1!$A:$J,MATCH('index match'!$K4,Sheet1!$C:$C,0),MATCH('index match'!N$2,Sheet1!$A$1:$J$1,0)) -> Middle Age
D5: Alina Russell | E5: =INDEX(Sheet1!$A:$J,MATCH('index match'!$D5,Sheet1!$C:$C,0),MATCH('index match'!E$2,Sheet1!$1:$1,0)) -> Russell | F5: =INDEX(Sheet1!$A:$J,MATCH('index match'!$D5,Sheet1!$C:$C,0),MATCH('index match'!F$2,Sheet1!$1:$1,0)) -> 0 | G5: =INDEX(Sheet1!$A:$J,MATCH('index match'!$D5,Sheet1!$C:$C,0),MATCH('index match'!G$2,Sheet1!$1:$1,0)) -> Old | K5: Vanessa Farrell | L5: =INDEX(Sheet1!$A:$J,MATCH('index match'!$K5,Sheet1!$C:$C,0),MATCH('index match'!L$2,Sheet1!$A$1:$J$1,0)) -> Farrell | M5: =INDEX(Sheet1!$A:$J,MATCH('index match'!$K5,Sheet1!$C:$C,0),MATCH('index match'!M$2,Sheet1!$A$1:$J$1,0)) -> 2 | N5: =INDEX(Sheet1!$A:$J,MATCH('index match'!$K5,Sheet1!$C:$C,0),MATCH('index match'!N$2,Sheet1!$A$1:$J$1,0)) -> Young
D6: Tiana Wright | E6: =INDEX(Sheet1!$A:$J,MATCH('index match'!$D6,Sheet1!$C:$C,0),MATCH('index match'!E$2,Sheet1!$1:$1,0)) -> Wright | F6: =INDEX(Sheet1!$A:$J,MATCH('index match'!$D6,Sheet1!$C:$C,0),MATCH('index match'!F$2,Sheet1!$1:$1,0)) -> 4 | G6: =INDEX(Sheet1!$A:$J,MATCH('index match'!$D6,Sheet1!$C:$C,0),MATCH('index match'!G$2,Sheet1!$1:$1,0)) -> Old | K6: Fenton Harrison | L6: =INDEX(Sheet1!$A:$J,MATCH('index match'!$K6,Sheet1!$C:$C,0),MATCH('index match'!L$2,Sheet1!$A$1:$J$1,0)) -> Harrison | M6: =INDEX(Sheet1!$A:$J,MATCH('index match'!$K6,Sheet1!$C:$C,0),MATCH('index match'!M$2,Sheet1!$A$1:$J$1,0)) -> 0 | N6: =INDEX(Sheet1!$A:$J,MATCH('index match'!$K6,Sheet1!$C:$C,0),MATCH('index match'!N$2,Sheet1!$A$1:$J$1,0)) -> Young
D7: Kimberly Rogers | E7: =INDEX(Sheet1!$A:$J,MATCH('index match'!$D7,Sheet1!$C:$C,0),MATCH('index match'!E$2,Sheet1!$1:$1,0)) -> Rogers | F7: =INDEX(Sheet1!$A:$J,MATCH('index match'!$D7,Sheet1!$C:$C,0),MATCH('index match'!F$2,Sheet1!$1:$1,0)) -> 2 | G7: =INDEX(Sheet1!$A:$J,MATCH('index match'!$D7,Sheet1!$C:$C,0),MATCH('index match'!G$2,Sheet1!$1:$1,0)) -> Old | K7: Belinda Spencer | L7: =INDEX(Sheet1!$A:$J,MATCH('index match'!$K7,Sheet1!$C:$C,0),MATCH('index match'!L$2,Sheet1!$A$1:$J$1,0)) -> Spencer | M7: =INDEX(Sheet1!$A:$J,MATCH('index match'!$K7,Sheet1!$C:$C,0),MATCH('index match'!M$2,Sheet1!$A$1:$J$1,0)) -> 5 | N7: =INDEX(Sheet1!$A:$J,MATCH('index match'!$K7,Sheet1!$C:$C,0),MATCH('index match'!N$2,Sheet1!$A$1:$J$1,0)) -> Young
D8: Amelia Craig | E8: =INDEX(Sheet1!$A:$J,MATCH('index match'!$D8,Sheet1!$C:$C,0),MATCH('index match'!E$2,Sheet1!$1:$1,0)) -> Craig | F8: =INDEX(Sheet1!$A:$J,MATCH('index match'!$D8,Sheet1!$C:$C,0),MATCH('index match'!F$2,Sheet1!$1:$1,0)) -> 2 | G8: =INDEX(Sheet1!$A:$J,MATCH('index match'!$D8,Sheet1!$C:$C,0),MATCH('index match'!G$2,Sheet1!$1:$1,0)) -> Old | K8: Ashton Farrell | L8: =INDEX(Sheet1!$A:$J,MATCH('index match'!$K8,Sheet1!$C:$C,0),MATCH('index match'!L$2,Sheet1!$A$1:$J$1,0)) -> Farrell | M8: =INDEX(Sheet1!$A:$J,MATCH('index match'!$K8,Sheet1!$C:$C,0),MATCH('index match'!M$2,Sheet1!$A$1:$J$1,0)) -> 1 | N8: =INDEX(Sheet1!$A:$J,MATCH('index match'!$K8,Sheet1!$C:$C,0),MATCH('index match'!N$2,Sheet1!$A$1:$J$1,0)) -> Young
D9: Connie Martin | E9: =INDEX(Sheet1!$A:$J,MATCH('index match'!$D9,Sheet1!$C:$C,0),MATCH('index match'!E$2,Sheet1!$1:$1,0)) -> Martin | F9: =INDEX(Sheet1!$A:$J,MATCH('index match'!$D9,Sheet1!$C:$C,0),MATCH('index match'!F$2,Sheet1!$1:$1,0)) -> 1 | G9: =INDEX(Sheet1!$A:$J,MATCH('index match'!$D9,Sheet1!$C:$C,0),MATCH('index match'!G$2,Sheet1!$1:$1,0)) -> Old | K9: Kellan Williams | L9: =INDEX(Sheet1!$A:$J,MATCH('index match'!$K9,Sheet1!$C:$C,0),MATCH('index match'!L$2,Sheet1!$A$1:$J$1,0)) -> Williams | M9: =INDEX(Sheet1!$A:$J,MATCH('index match'!$K9,Sheet1!$C:$C,0),MATCH('index match'!M$2,Sheet1!$A$1:$J$1,0)) -> 4 | N9: =INDEX(Sheet1!$A:$J,MATCH('index match'!$K9,Sheet1!$C:$C,0),MATCH('index match'!N$2,Sheet1!$A$1:$J$1,0)) -> Middle Age
D10: Steven Johnson | E10: =INDEX(Sheet1!$A:$J,MATCH('index match'!$D10,Sheet1!$C:$C,0),MATCH('index match'!E$2,Sheet1!$1:$1,0)) -> Johnson | F10: =INDEX(Sheet1!$A:$J,MATCH('index match'!$D10,Sheet1!$C:$C,0),MATCH('index match'!F$2,Sheet1!$1:$1,0)) -> 5 | G10: =INDEX(Sheet1!$A:$J,MATCH('index match'!$D10,Sheet1!$C:$C,0),MATCH('index match'!G$2,Sheet1!$1:$1,0)) -> Middle Age | K10: Tyler Davis | L10: =INDEX(Sheet1!$A:$J,MATCH('index match'!$K10,Sheet1!$C:$C,0),MATCH('index match'!L$2,Sheet1!$A$1:$J$1,0)) -> Davis | M10: =INDEX(Sheet1!$A:$J,MATCH('index match'!$K10,Sheet1!$C:$C,0),MATCH('index match'!M$2,Sheet1!$A$1:$J$1,0)) -> 1 | N10: =INDEX(Sheet1!$A:$J,MATCH('index match'!$K10,Sheet1!$C:$C,0),MATCH('index match'!N$2,Sheet1!$A$1:$J$1,0)) -> Old
D11: Charlie Hall | E11: =INDEX(Sheet1!$A:$J,MATCH('index match'!$D11,Sheet1!$C:$C,0),MATCH('index match'!E$2,Sheet1!$1:$1,0)) -> Hall | F11: =INDEX(Sheet1!$A:$J,MATCH('index match'!$D11,Sheet1!$C:$C,0),MATCH('index match'!F$2,Sheet1!$1:$1,0)) -> 4 | G11: =INDEX(Sheet1!$A:$J,MATCH('index match'!$D11,Sheet1!$C:$C,0),MATCH('index match'!G$2,Sheet1!$1:$1,0)) -> Middle Age | K11: Edgar Thomas | L11: =INDEX(Sheet1!$A:$J,MATCH('index match'!$K11,Sheet1!$C:$C,0),MATCH('index match'!L$2,Sheet1!$A$1:$J$1,0)) -> Thomas | M11: =INDEX(Sheet1!$A:$J,MATCH('index match'!$K11,Sheet1!$C:$C,0),MATCH('index match'!M$2,Sheet1!$A$1:$J$1,0)) -> 3 | N11: =INDEX(Sheet1!$A:$J,MATCH('index match'!$K11,Sheet1!$C:$C,0),MATCH('index match'!N$2,Sheet1!$A$1:$J$1,0)) -> Middle Age
D12: Richard Richards | E12: =INDEX(Sheet1!$A:$J,MATCH('index match'!$D12,Sheet1!$C:$C,0),MATCH('index match'!E$2,Sheet1!$1:$1,0)) -> Richards | F12: =INDEX(Sheet1!$A:$J,MATCH('index match'!$D12,Sheet1!$C:$C,0),MATCH('index match'!F$2,Sheet1!$1:$1,0)) -> 2 | G12: =INDEX(Sheet1!$A:$J,MATCH('index match'!$D12,Sheet1!$C:$C,0),MATCH('index match'!G$2,Sheet1!$1:$1,0)) -> Old | K12: Nicholas Owens | L12: =INDEX(Sheet1!$A:$J,MATCH('index match'!$K12,Sheet1!$C:$C,0),MATCH('index match'!L$2,Sheet1!$A$1:$J$1,0)) -> Owens | M12: =INDEX(Sheet1!$A:$J,MATCH('index match'!$K12,Sheet1!$C:$C,0),MATCH('index match'!M$2,Sheet1!$A$1:$J$1,0)) -> 3 | N12: =INDEX(Sheet1!$A:$J,MATCH('index match'!$K12,Sheet1!$C:$C,0),MATCH('index match'!N$2,Sheet1!$A$1:$J$1,0)) -> Middle Age
D13: Alan Allen | E13: =INDEX(Sheet1!$A:$J,MATCH('index match'!$D13,Sheet1!$C:$C,0),MATCH('index match'!E$2,Sheet1!$1:$1,0)) -> Allen | F13: =INDEX(Sheet1!$A:$J,MATCH('index match'!$D13,Sheet1!$C:$C,0),MATCH('index match'!F$2,Sheet1!$1:$1,0)) -> 2 | G13: =INDEX(Sheet1!$A:$J,MATCH('index match'!$D13,Sheet1!$C:$C,0),MATCH('index match'!G$2,Sheet1!$1:$1,0)) -> Old | K13: Sawyer Carter | L13: =INDEX(Sheet1!$A:$J,MATCH('index match'!$K13,Sheet1!$C:$C,0),MATCH('index match'!L$2,Sheet1!$A$1:$J$1,0)) -> Carter | M13: =INDEX(Sheet1!$A:$J,MATCH('index match'!$K13,Sheet1!$C:$C,0),MATCH('index match'!M$2,Sheet1!$A$1:$J$1,0)) -> 4 | N13: =INDEX(Sheet1!$A:$J,MATCH('index match'!$K13,Sheet1!$C:$C,0),MATCH('index match'!N$2,Sheet1!$A$1:$J$1,0)) -> Young
D14: Tiana Farrell | E14: =INDEX(Sheet1!$A:$J,MATCH('index match'!$D14,Sheet1!$C:$C,0),MATCH('index match'!E$2,Sheet1!$1:$1,0)) -> Farrell | F14: =INDEX(Sheet1!$A:$J,MATCH('index match'!$D14,Sheet1!$C:$C,0),MATCH('index match'!F$2,Sheet1!$1:$1,0)) -> 0 | G14: =INDEX(Sheet1!$A:$J,MATCH('index match'!$D14,Sheet1!$C:$C,0),MATCH('index match'!G$2,Sheet1!$1:$1,0)) -> Middle Age | K14: Lyndon Parker | L14: =INDEX(Sheet1!$A:$J,MATCH('index match'!$K14,Sheet1!$C:$C,0),MATCH('index match'!L$2,Sheet1!$A$1:$J$1,0)) -> Parker | M14: =INDEX(Sheet1!$A:$J,MATCH('index match'!$K14,Sheet1!$C:$C,0),MATCH('index match'!M$2,Sheet1!$A$1:$J$1,0)) -> 1 | N14: =INDEX(Sheet1!$A:$J,MATCH('index match'!$K14,Sheet1!$C:$C,0),MATCH('index match'!N$2,Sheet1!$A$1:$J$1,0)) -> Middle Age
D15: Emily Chapman | E15: =INDEX(Sheet1!$A:$J,MATCH('index match'!$D15,Sheet1!$C:$C,0),MATCH('index match'!E$2,Sheet1!$1:$1,0)) -> Chapman | F15: =INDEX(Sheet1!$A:$J,MATCH('index match'!$D15,Sheet1!$C:$C,0),MATCH('index match'!F$2,Sheet1!$1:$1,0)) -> 0 | G15: =INDEX(Sheet1!$A:$J,MATCH('index match'!$D15,Sheet1!$C:$C,0),MATCH('index match'!G$2,Sheet1!$1:$1,0)) -> Middle Age | K15: Sofia Barnes | L15: =INDEX(Sheet1!$A:$J,MATCH('index match'!$K15,Sheet1!$C:$C,0),MATCH('index match'!L$2,Sheet1!$A$1:$J$1,0)) -> Barnes | M15: =INDEX(Sheet1!$A:$J,MATCH('index match'!$K15,Sheet1!$C:$C,0),MATCH('index match'!M$2,Sheet1!$A$1:$J$1,0)) -> 5 | N15: =INDEX(Sheet1!$A:$J,MATCH('index match'!$K15,Sheet1!$C:$C,0),MATCH('index match'!N$2,Sheet1!$A$1:$J$1,0)) -> Old
... D489: Victoria Richards | E489: =INDEX(Sheet1!$A:$J,MATCH('index match'!$D489,Sheet1!$C:$C,0),MATCH('index match'!E$2,Sheet1!$1:$1,0)) -> Richards | F489: =INDEX(Sheet1!$A:$J,MATCH('index match'!$D489,Sheet1!$C:$C,0),MATCH('index match'!F$2,Sheet1!$1:$1,0)) -> 1 | G489: =INDEX(Sheet1!$A:$J,MATCH('index match'!$D489,Sheet1!$C:$C,0),MATCH('index match'!G$2,Sheet1!$1:$1,0)) -> Old | K489: Aiden Chapman | L489: =INDEX(Sheet1!$A:$J,MATCH('index match'!$K489,Sheet1!$C:$C,0),MATCH('index match'!L$2,Sheet1!$A$1:$J$1,0)) -> Chapman | M489: =INDEX(Sheet1!$A:$J,MATCH('index match'!$K489,Sheet1!$C:$C,0),MATCH('index match'!M$2,Sheet1!$A$1:$J$1,0)) -> 1 | N489: =INDEX(Sheet1!$A:$J,MATCH('index match'!$K489,Sheet1!$C:$C,0),MATCH('index match'!N$2,Sheet1!$A$1:$J$1,0)) -> Middle Age
D490: Bruce Ellis | E490: =INDEX(Sheet1!$A:$J,MATCH('index match'!$D490,Sheet1!$C:$C,0),MATCH('index match'!E$2,Sheet1!$1:$1,0)) -> Ellis | F490: =INDEX(Sheet1!$A:$J,MATCH('index match'!$D490,Sheet1!$C:$C,0),MATCH('index match'!F$2,Sheet1!$1:$1,0)) -> 4 | G490: =INDEX(Sheet1!$A:$J,MATCH('index match'!$D490,Sheet1!$C:$C,0),MATCH('index match'!G$2,Sheet1!$1:$1,0)) -> Middle Age
D491: Preston Harper | E491: =INDEX(Sheet1!$A:$J,MATCH('index match'!$D491,Sheet1!$C:$C,0),MATCH('index match'!E$2,Sheet1!$1:$1,0)) -> Harper | F491: =INDEX(Sheet1!$A:$J,MATCH('index match'!$D491,Sheet1!$C:$C,0),MATCH('index match'!F$2,Sheet1!$1:$1,0)) -> 5 | G491: =INDEX(Sheet1!$A:$J,MATCH('index match'!$D491,Sheet1!$C:$C,0),MATCH('index match'!G$2,Sheet1!$1:$1,0)) -> Old
D492: Roman Cole | E492: =INDEX(Sheet1!$A:$J,MATCH('index match'!$D492,Sheet1!$C:$C,0),MATCH('index match'!E$2,Sheet1!$1:$1,0)) -> Cole | F492: =INDEX(Sheet1!$A:$J,MATCH('index match'!$D492,Sheet1!$C:$C,0),MATCH('index match'!F$2,Sheet1!$1:$1,0)) -> 1 | G492: =INDEX(Sheet1!$A:$J,MATCH('index match'!$D492,Sheet1!$C:$C,0),MATCH('index match'!G$2,Sheet1!$1:$1,0)) -> Middle Age
D493: Chloe Gibson | E493: =INDEX(Sheet1!$A:$J,MATCH('index match'!$D493,Sheet1!$C:$C,0),MATCH('index match'!E$2,Sheet1!$1:$1,0)) -> Gibson | F493: =INDEX(Sheet1!$A:$J,MATCH('index match'!$D493,Sheet1!$C:$C,0),MATCH('index match'!F$2,Sheet1!$1:$1,0)) -> 2 | G493: =INDEX(Sheet1!$A:$J,MATCH('index match'!$D493,Sheet1!$C:$C,0),MATCH('index match'!G$2,Sheet1!$1:$1,0)) -> Middle Age
D494: Amy Wilson | E494: =INDEX(Sheet1!$A:$J,MATCH('index match'!$D494,Sheet1!$C:$C,0),MATCH('index match'!E$2,Sheet1!$1:$1,0)) -> Wilson | F494: =INDEX(Sheet1!$A:$J,MATCH('index match'!$D494,Sheet1!$C:$C,0),MATCH('index match'!F$2,Sheet1!$1:$1,0)) -> 3 | G494: =INDEX(Sheet1!$A:$J,MATCH('index match'!$D494,Sheet1!$C:$C,0),MATCH('index match'!G$2,Sheet1!$1:$1,0)) -> Middle Age
D495: Nicholas Taylor | E495: =INDEX(Sheet1!$A:$J,MATCH('index match'!$D495,Sheet1!$C:$C,0),MATCH('index match'!E$2,Sheet1!$1:$1,0)) -> Taylor | F495: =INDEX(Sheet1!$A:$J,MATCH('index match'!$D495,Sheet1!$C:$C,0),MATCH('index match'!F$2,Sheet1!$1:$1,0)) -> 4 | G495: =INDEX(Sheet1!$A:$J,MATCH('index match'!$D495,Sheet1!$C:$C,0),MATCH('index match'!G$2,Sheet1!$1:$1,0)) -> Young
D496: Edwin Crawford | E496: =INDEX(Sheet1!$A:$J,MATCH('index match'!$D496,Sheet1!$C:$C,0),MATCH('index match'!E$2,Sheet1!$1:$1,0)) -> Crawford | F496: =INDEX(Sheet1!$A:$J,MATCH('index match'!$D496,Sheet1!$C:$C,0),MATCH('index match'!F$2,Sheet1!$1:$1,0)) -> 4 | G496: =INDEX(Sheet1!$A:$J,MATCH('index match'!$D496,Sheet1!$C:$C,0),MATCH('index match'!G$2,Sheet1!$1:$1,0)) -> Middle Age
D497: Ashton Williams | E497: =INDEX(Sheet1!$A:$J,MATCH('index match'!$D497,Sheet1!$C:$C,0),MATCH('index match'!E$2,Sheet1!$1:$1,0)) -> Williams | F497: =INDEX(Sheet1!$A:$J,MATCH('index match'!$D497,Sheet1!$C:$C,0),MATCH('index match'!F$2,Sheet1!$1:$1,0)) -> 5 | G497: =INDEX(Sheet1!$A:$J,MATCH('index match'!$D497,Sheet1!$C:$C,0),MATCH('index match'!G$2,Sheet1!$1:$1,0)) -> Young
D498: Cadie Richards | E498: =INDEX(Sheet1!$A:$J,MATCH('index match'!$D498,Sheet1!$C:$C,0),MATCH('index match'!E$2,Sheet1!$1:$1,0)) -> Richards | F498: =INDEX(Sheet1!$A:$J,MATCH('index match'!$D498,Sheet1!$C:$C,0),MATCH('index match'!F$2,Sheet1!$1:$1,0)) -> 3 | G498: =INDEX(Sheet1!$A:$J,MATCH('index match'!$D498,Sheet1!$C:$C,0),MATCH('index match'!G$2,Sheet1!$1:$1,0)) -> Middle Age
D499: Reid Scott | E499: =INDEX(Sheet1!$A:$J,MATCH('index match'!$D499,Sheet1!$C:$C,0),MATCH('index match'!E$2,Sheet1!$1:$1,0)) -> Scott | F499: =INDEX(Sheet1!$A:$J,MATCH('index match'!$D499,Sheet1!$C:$C,0),MATCH('index match'!F$2,Sheet1!$1:$1,0)) -> 5 | G499: =INDEX(Sheet1!$A:$J,MATCH('index match'!$D499,Sheet1!$C:$C,0),MATCH('index match'!G$2,Sheet1!$1:$1,0)) -> Middle Age
D500: Briony Tucker | E500: =INDEX(Sheet1!$A:$J,MATCH('index match'!$D500,Sheet1!$C:$C,0),MATCH('index match'!E$2,Sheet1!$1:$1,0)) -> Tucker | F500: =INDEX(Sheet1!$A:$J,MATCH('index match'!$D500,Sheet1!$C:$C,0),MATCH('index match'!F$2,Sheet1!$1:$1,0)) -> 1 | G500: =INDEX(Sheet1!$A:$J,MATCH('index match'!$D500,Sheet1!$C:$C,0),MATCH('index match'!G$2,Sheet1!$1:$1,0)) -> Middle Age
D501: Emily Smith | E501: =INDEX(Sheet1!$A:$J,MATCH('index match'!$D501,Sheet1!$C:$C,0),MATCH('index match'!E$2,Sheet1!$1:$1,0)) -> Smith | F501: =INDEX(Sheet1!$A:$J,MATCH('index match'!$D501,Sheet1!$C:$C,0),MATCH('index match'!F$2,Sheet1!$1:$1,0)) -> 3 | G501: =INDEX(Sheet1!$A:$J,MATCH('index match'!$D501,Sheet1!$C:$C,0),MATCH('index match'!G$2,Sheet1!$1:$1,0)) -> Middle Age
... D515: Dexter Williams | E515: =INDEX(Sheet1!$A:$J,MATCH('index match'!$D515,Sheet1!$C:$C,0),MATCH('index match'!E$2,Sheet1!$1:$1,0)) -> Williams | F515: =INDEX(Sheet1!$A:$J,MATCH('index match'!$D515,Sheet1!$C:$C,0),MATCH('index match'!F$2,Sheet1!$1:$1,0)) -> 0 | G515: =INDEX(Sheet1!$A:$J,MATCH('index match'!$D515,Sheet1!$C:$C,0),MATCH('index match'!G$2,Sheet1!$1:$1,0)) -> Old

Sheet Filter
C1: Marital Status | D1: Name | E1: Maritial Status | F1: No. of Children | I1: Marital Status | J1: Name | K1: Marital Status | L1: No. of Children
C2: married | D2: {=_xlfn._xlws.FILTER(_xlfn._xlws.FILTER(Sheet1!A:J,Sheet1!I:I=Filter!C2),{0,0,1,0,0,0,0,0,1,1})} -> Jacob Robinson | E2: Married | F2: 2 | I2: married | J2: {=_xlfn._xlws.FILTER(_xlfn._xlws.FILTER(Sheet1!A:J,Sheet1!I:I=Filter!I2),{0,0,1,0,0,0,0,0,1,1})} -> Jacob Robinson | K2: Married | L2: 2
D3: Grace Taylor | E3: Married | F3: 1 | J3: Grace Taylor | K3: Married | L3: 1
D4: Vanessa Farrell | E4: Married | F4: 2 | J4: Vanessa Farrell | K4: Married | L4: 2
D5: Fenton Harrison | E5: Married | F5: 0 | J5: Fenton Harrison | K5: Married | L5: 0
D6: Belinda Spencer | E6: Married | F6: 5 | J6: Belinda Spencer | K6: Married | L6: 5
D7: Ashton Farrell | E7: Married | F7: 1 | J7: Ashton Farrell | K7: Married | L7: 1
D8: Kellan Williams | E8: Married | F8: 4 | J8: Kellan Williams | K8: Married | L8: 4
D9: Tyler Davis | E9: Married | F9: 1 | J9: Tyler Davis | K9: Married | L9: 1
D10: Edgar Thomas | E10: Married | F10: 3 | J10: Edgar Thomas | K10: Married | L10: 3
D11: Nicholas Owens | E11: Married | F11: 3 | J11: Nicholas Owens | K11: Married | L11: 3
D12: Sawyer Carter | E12: Married | F12: 4 | J12: Sawyer Carter | K12: Married | L12: 4
D13: Lyndon Parker | E13: Married | F13: 1 | J13: Lyndon Parker | K13: Married | L13: 1
D14: Sofia Barnes | E14: Married | F14: 5 | J14: Sofia Barnes | K14: Married | L14: 5
... D488: Aiden Chapman | E488: Married | F488: 1 | J488: Aiden Chapman | K488: Married | L488: 1

Sheet Index_Match
B1: Gender | E1: First Name | F1: Gender | G1: Occupation | H1: Marital Status | I1: No. of Children | J1: Full Name | K1: No. of Children | L1: Last Name | M1: Age Bracket
B2: Female | E2: {=_xlfn._xlws.FILTER(Sheet1!A:A,Sheet1!D:D=Index_Match!B2)} -> Grace | F2: =IF(ISBLANK($E2),"",INDEX(Sheet1!$A:$J,MATCH(Index_Match!$E2,Sheet1!$A:$A,0),MATCH(Index_Match!F$1,Sheet1!$A$1:$J$1,0))) -> Female | G2: =IF(ISBLANK($E2),"",INDEX(Sheet1!$A:$J,MATCH(Index_Match!$E2,Sheet1!$A:$A,0),MATCH(Index_Match!G$1,Sheet1!$A$1:$J$1,0))) -> Insurer | H2: =IF(ISBLANK($E2),"",INDEX(Sheet1!$A:$J,MATCH(Index_Match!$E2,Sheet1!$A:$A,0),MATCH(Index_Match!H$1,Sheet1!$A$1:$J$1,0))) -> Married | I2: =IF(ISBLANK($E2),"",INDEX(Sheet1!$A:$J,MATCH(Index_Match!$E2,Sheet1!$A:$A,0),MATCH(Index_Match!I$1,Sheet1!$A$1:$J$1,0))) -> 1 | J2: =IF(ISBLANK($E2),"",INDEX(Sheet1!$A:$J,MATCH(Index_Match!$E2,Sheet1!$A:$A,0),MATCH(Index_Match!J$1,Sheet1!$A$1:$J$1,0))) -> Grace Taylor | K2: =IF(ISBLANK($E2),"",INDEX(Sheet1!$A:$J,MATCH(Index_Match!$E2,Sheet1!$A:$A,0),MATCH(Index_Match!K$1,Sheet1!$A$1:$J$1,0))) -> 1 | L2: =IF(ISBLANK($E2),"",INDEX(Sheet1!$A:$J,MATCH(Index_Match!$E2,Sheet1!$A:$A,0),MATCH(Index_Match!L$1,Sheet1!$A$1:$J$1,0))) -> Taylor | M2: =IF(ISBLANK($E2),"",INDEX(Sheet1!$A:$J,MATCH(Index_Match!$E2,Sheet1!$A:$A,0),MATCH(Index_Match!M$1,Sheet1!$A$1:$J$1,0))) -> Middle Age
E3: Vanessa | F3: =IF(ISBLANK($E3),"",INDEX(Sheet1!$A:$J,MATCH(Index_Match!$E3,Sheet1!$A:$A,0),MATCH(Index_Match!F$1,Sheet1!$A$1:$J$1,0))) -> Female | G3: =IF(ISBLANK($E3),"",INDEX(Sheet1!$A:$J,MATCH(Index_Match!$E3,Sheet1!$A:$A,0),MATCH(Index_Match!G$1,Sheet1!$A$1:$J$1,0))) -> Lawyer | H3: =IF(ISBLANK($E3),"",INDEX(Sheet1!$A:$J,MATCH(Index_Match!$E3,Sheet1!$A:$A,0),MATCH(Index_Match!H$1,Sheet1!$A$1:$J$1,0))) -> Married | I3: =IF(ISBLANK($E3),"",INDEX(Sheet1!$A:$J,MATCH(Index_Match!$E3,Sheet1!$A:$A,0),MATCH(Index_Match!I$1,Sheet1!$A$1:$J$1,0))) -> 2 | J3: =IF(ISBLANK($E3),"",INDEX(Sheet1!$A:$J,MATCH(Index_Match!$E3,Sheet1!$A:$A,0),MATCH(Index_Match!J$1,Sheet1!$A$1:$J$1,0))) -> Vanessa Farrell | K3: =IF(ISBLANK($E3),"",INDEX(Sheet1!$A:$J,MATCH(Index_Match!$E3,Sheet1!$A:$A,0),MATCH(Index_Match!K$1,Sheet1!$A$1:$J$1,0))) -> 2 | L3: =IF(ISBLANK($E3),"",INDEX(Sheet1!$A:$J,MATCH(Index_Match!$E3,Sheet1!$A:$A,0),MATCH(Index_Match!L$1,Sheet1!$A$1:$J$1,0))) -> Farrell | M3: =IF(ISBLANK($E3),"",INDEX(Sheet1!$A:$J,MATCH(Index_Match!$E3,Sheet1!$A:$A,0),MATCH(Index_Match!M$1,Sheet1!$A$1:$J$1,0))) -> Young
E4: Belinda | F4: =IF(ISBLANK($E4),"",INDEX(Sheet1!$A:$J,MATCH(Index_Match!$E4,Sheet1!$A:$A,0),MATCH(Index_Match!F$1,Sheet1!$A$1:$J$1,0))) -> Female | G4: =IF(ISBLANK($E4),"",INDEX(Sheet1!$A:$J,MATCH(Index_Match!$E4,Sheet1!$A:$A,0),MATCH(Index_Match!G$1,Sheet1!$A$1:$J$1,0))) -> Dancer | H4: =IF(ISBLANK($E4),"",INDEX(Sheet1!$A:$J,MATCH(Index_Match!$E4,Sheet1!$A:$A,0),MATCH(Index_Match!H$1,Sheet1!$A$1:$J$1,0))) -> Married | I4: =IF(ISBLANK($E4),"",INDEX(Sheet1!$A:$J,MATCH(Index_Match!$E4,Sheet1!$A:$A,0),MATCH(Index_Match!I$1,Sheet1!$A$1:$J$1,0))) -> 5 | J4: =IF(ISBLANK($E4),"",INDEX(Sheet1!$A:$J,MATCH(Index_Match!$E4,Sheet1!$A:$A,0),MATCH(Index_Match!J$1,Sheet1!$A$1:$J$1,0))) -> Belinda Spencer | K4: =IF(ISBLANK($E4),"",INDEX(Sheet1!$A:$J,MATCH(Index_Match!$E4,Sheet1!$A:$A,0),MATCH(Index_Match!K$1,Sheet1!$A$1:$J$1,0))) -> 5 | L4: =IF(ISBLANK($E4),"",INDEX(Sheet1!$A:$J,MATCH(Index_Match!$E4,Sheet1!$A:$A,0),MATCH(Index_Match!L$1,Sheet1!$A$1:$J$1,0))) -> Spencer | M4: =IF(ISBLANK($E4),"",INDEX(Sheet1!$A:$J,MATCH(Index_Match!$E4,Sheet1!$A:$A,0),MATCH(Index_Match!M$1,Sheet1!$A$1:$J$1,0))) -> Young
E5: Alina | F5: =IF(ISBLANK($E5),"",INDEX(Sheet1!$A:$J,MATCH(Index_Match!$E5,Sheet1!$A:$A,0),MATCH(Index_Match!F$1,Sheet1!$A$1:$J$1,0))) -> Female | G5: =IF(ISBLANK($E5),"",INDEX(Sheet1!$A:$J,MATCH(Index_Match!$E5,Sheet1!$A:$A,0),MATCH(Index_Match!G$1,Sheet1!$A$1:$J$1,0))) -> Engineer | H5: =IF(ISBLANK($E5),"",INDEX(Sheet1!$A:$J,MATCH(Index_Match!$E5,Sheet1!$A:$A,0),MATCH(Index_Match!H$1,Sheet1!$A$1:$J$1,0))) -> Single | I5: =IF(ISBLANK($E5),"",INDEX(Sheet1!$A:$J,MATCH(Index_Match!$E5,Sheet1!$A:$A,0),MATCH(Index_Match!I$1,Sheet1!$A$1:$J$1,0))) -> 0 | J5: =IF(ISBLANK($E5),"",INDEX(Sheet1!$A:$J,MATCH(Index_Match!$E5,Sheet1!$A:$A,0),MATCH(Index_Match!J$1,Sheet1!$A$1:$J$1,0))) -> Alina Russell | K5: =IF(ISBLANK($E5),"",INDEX(Sheet1!$A:$J,MATCH(Index_Match!$E5,Sheet1!$A:$A,0),MATCH(Index_Match!K$1,Sheet1!$A$1:$J$1,0))) -> 0 | L5: =IF(ISBLANK($E5),"",INDEX(Sheet1!$A:$J,MATCH(Index_Match!$E5,Sheet1!$A:$A,0),MATCH(Index_Match!L$1,Sheet1!$A$1:$J$1,0))) -> Russell | M5: =IF(ISBLANK($E5),"",INDEX(Sheet1!$A:$J,MATCH(Index_Match!$E5,Sheet1!$A:$A,0),MATCH(Index_Match!M$1,Sheet1!$A$1:$J$1,0))) -> Old
E6: Tiana | F6: =IF(ISBLANK($E6),"",INDEX(Sheet1!$A:$J,MATCH(Index_Match!$E6,Sheet1!$A:$A,0),MATCH(Index_Match!F$1,Sheet1!$A$1:$J$1,0))) -> Female | G6: =IF(ISBLANK($E6),"",INDEX(Sheet1!$A:$J,MATCH(Index_Match!$E6,Sheet1!$A:$A,0),MATCH(Index_Match!G$1,Sheet1!$A$1:$J$1,0))) -> Composer | H6: =IF(ISBLANK($E6),"",INDEX(Sheet1!$A:$J,MATCH(Index_Match!$E6,Sheet1!$A:$A,0),MATCH(Index_Match!H$1,Sheet1!$A$1:$J$1,0))) -> Single | I6: =IF(ISBLANK($E6),"",INDEX(Sheet1!$A:$J,MATCH(Index_Match!$E6,Sheet1!$A:$A,0),MATCH(Index_Match!I$1,Sheet1!$A$1:$J$1,0))) -> 4 | J6: =IF(ISBLANK($E6),"",INDEX(Sheet1!$A:$J,MATCH(Index_Match!$E6,Sheet1!$A:$A,0),MATCH(Index_Match!J$1,Sheet1!$A$1:$J$1,0))) -> Tiana Wright | K6: =IF(ISBLANK($E6),"",INDEX(Sheet1!$A:$J,MATCH(Index_Match!$E6,Sheet1!$A:$A,0),MATCH(Index_Match!K$1,Sheet1!$A$1:$J$1,0))) -> 4 | L6: =IF(ISBLANK($E6),"",INDEX(Sheet1!$A:$J,MATCH(Index_Match!$E6,Sheet1!$A:$A,0),MATCH(Index_Match!L$1,Sheet1!$A$1:$J$1,0))) -> Wright | M6: =IF(ISBLANK($E6),"",INDEX(Sheet1!$A:$J,MATCH(Index_Match!$E6,Sheet1!$A:$A,0),MATCH(Index_Match!M$1,Sheet1!$A$1:$J$1,0))) -> Old
E7: Kimberly | F7: =IF(ISBLANK($E7),"",INDEX(Sheet1!$A:$J,MATCH(Index_Match!$E7,Sheet1!$A:$A,0),MATCH(Index_Match!F$1,Sheet1!$A$1:$J$1,0))) -> Female | G7: =IF(ISBLANK($E7),"",INDEX(Sheet1!$A:$J,MATCH(Index_Match!$E7,Sheet1!$A:$A,0),MATCH(Index_Match!G$1,Sheet1!$A$1:$J$1,0))) -> Geologist | H7: =IF(ISBLANK($E7),"",INDEX(Sheet1!$A:$J,MATCH(Index_Match!$E7,Sheet1!$A:$A,0),MATCH(Index_Match!H$1,Sheet1!$A$1:$J$1,0))) -> Single | I7: =IF(ISBLANK($E7),"",INDEX(Sheet1!$A:$J,MATCH(Index_Match!$E7,Sheet1!$A:$A,0),MATCH(Index_Match!I$1,Sheet1!$A$1:$J$1,0))) -> 2 | J7: =IF(ISBLANK($E7),"",INDEX(Sheet1!$A:$J,MATCH(Index_Match!$E7,Sheet1!$A:$A,0),MATCH(Index_Match!J$1,Sheet1!$A$1:$J$1,0))) -> Kimberly Rogers | K7: =IF(ISBLANK($E7),"",INDEX(Sheet1!$A:$J,MATCH(Index_Match!$E7,Sheet1!$A:$A,0),MATCH(Index_Match!K$1,Sheet1!$A$1:$J$1,0))) -> 2 | L7: =IF(ISBLANK($E7),"",INDEX(Sheet1!$A:$J,MATCH(Index_Match!$E7,Sheet1!$A:$A,0),MATCH(Index_Match!L$1,Sheet1!$A$1:$J$1,0))) -> Rogers | M7: =IF(ISBLANK($E7),"",INDEX(Sheet1!$A:$J,MATCH(Index_Match!$E7,Sheet1!$A:$A,0),MATCH(Index_Match!M$1,Sheet1!$A$1:$J$1,0))) -> Old
E8: Amelia | F8: =IF(ISBLANK($E8),"",INDEX(Sheet1!$A:$J,MATCH(Index_Match!$E8,Sheet1!$A:$A,0),MATCH(Index_Match!F$1,Sheet1!$A$1:$J$1,0))) -> Female | G8: =IF(ISBLANK($E8),"",INDEX(Sheet1!$A:$J,MATCH(Index_Match!$E8,Sheet1!$A:$A,0),MATCH(Index_Match!G$1,Sheet1!$A$1:$J$1,0))) -> Scientist | H8: =IF(ISBLANK($E8),"",INDEX(Sheet1!$A:$J,MATCH(Index_Match!$E8,Sheet1!$A:$A,0),MATCH(Index_Match!H$1,Sheet1!$A$1:$J$1,0))) -> Single | I8: =IF(ISBLANK($E8),"",INDEX(Sheet1!$A:$J,MATCH(Index_Match!$E8,Sheet1!$A:$A,0),MATCH(Index_Match!I$1,Sheet1!$A$1:$J$1,0))) -> 2 | J8: =IF(ISBLANK($E8),"",INDEX(Sheet1!$A:$J,MATCH(Index_Match!$E8,Sheet1!$A:$A,0),MATCH(Index_Match!J$1,Sheet1!$A$1:$J$1,0))) -> Amelia Craig | K8: =IF(ISBLANK($E8),"",INDEX(Sheet1!$A:$J,MATCH(Index_Match!$E8,Sheet1!$A:$A,0),MATCH(Index_Match!K$1,Sheet1!$A$1:$J$1,0))) -> 2 | L8: =IF(ISBLANK($E8),"",INDEX(Sheet1!$A:$J,MATCH(Index_Match!$E8,Sheet1!$A:$A,0),MATCH(Index_Match!L$1,Sheet1!$A$1:$J$1,0))) -> Craig | M8: =IF(ISBLANK($E8),"",INDEX(Sheet1!$A:$J,MATCH(Index_Match!$E8,Sheet1!$A:$A,0),MATCH(Index_Match!M$1,Sheet1!$A$1:$J$1,0))) -> Old
E9: Connie | F9: =IF(ISBLANK($E9),"",INDEX(Sheet1!$A:$J,MATCH(Index_Match!$E9,Sheet1!$A:$A,0),MATCH(Index_Match!F$1,Sheet1!$A$1:$J$1,0))) -> Female | G9: =IF(ISBLANK($E9),"",INDEX(Sheet1!$A:$J,MATCH(Index_Match!$E9,Sheet1!$A:$A,0),MATCH(Index_Match!G$1,Sheet1!$A$1:$J$1,0))) -> Economist | H9: =IF(ISBLANK($E9),"",INDEX(Sheet1!$A:$J,MATCH(Index_Match!$E9,Sheet1!$A:$A,0),MATCH(Index_Match!H$1,Sheet1!$A$1:$J$1,0))) -> Single | I9: =IF(ISBLANK($E9),"",INDEX(Sheet1!$A:$J,MATCH(Index_Match!$E9,Sheet1!$A:$A,0),MATCH(Index_Match!I$1,Sheet1!$A$1:$J$1,0))) -> 1 | J9: =IF(ISBLANK($E9),"",INDEX(Sheet1!$A:$J,MATCH(Index_Match!$E9,Sheet1!$A:$A,0),MATCH(Index_Match!J$1,Sheet1!$A$1:$J$1,0))) -> Connie Martin | K9: =IF(ISBLANK($E9),"",INDEX(Sheet1!$A:$J,MATCH(Index_Match!$E9,Sheet1!$A:$A,0),MATCH(Index_Match!K$1,Sheet1!$A$1:$J$1,0))) -> 1 | L9: =IF(ISBLANK($E9),"",INDEX(Sheet1!$A:$J,MATCH(Index_Match!$E9,Sheet1!$A:$A,0),MATCH(Index_Match!L$1,Sheet1!$A$1:$J$1,0))) -> Martin | M9: =IF(ISBLANK($E9),"",INDEX(Sheet1!$A:$J,MATCH(Index_Match!$E9,Sheet1!$A:$A,0),MATCH(Index_Match!M$1,Sheet1!$A$1:$J$1,0))) -> Old
E10: Tiana | F10: =IF(ISBLANK($E10),"",INDEX(Sheet1!$A:$J,MATCH(Index_Match!$E10,Sheet1!$A:$A,0),MATCH(Index_Match!F$1,Sheet1!$A$1:$J$1,0))) -> Female | G10: =IF(ISBLANK($E10),"",INDEX(Sheet1!$A:$J,MATCH(Index_Match!$E10,Sheet1!$A:$A,0),MATCH(Index_Match!G$1,Sheet1!$A$1:$J$1,0))) -> Composer | H10: =IF(ISBLANK($E10),"",INDEX(Sheet1!$A:$J,MATCH(Index_Match!$E10,Sheet1!$A:$A,0),MATCH(Index_Match!H$1,Sheet1!$A$1:$J$1,0))) -> Single | I10: =IF(ISBLANK($E10),"",INDEX(Sheet1!$A:$J,MATCH(Index_Match!$E10,Sheet1!$A:$A,0),MATCH(Index_Match!I$1,Sheet1!$A$1:$J$1,0))) -> 4 | J10: =IF(ISBLANK($E10),"",INDEX(Sheet1!$A:$J,MATCH(Index_Match!$E10,Sheet1!$A:$A,0),MATCH(Index_Match!J$1,Sheet1!$A$1:$J$1,0))) -> Tiana Wright | K10: =IF(ISBLANK($E10),"",INDEX(Sheet1!$A:$J,MATCH(Index_Match!$E10,Sheet1!$A:$A,0),MATCH(Index_Match!K$1,Sheet1!$A$1:$J$1,0))) -> 4 | L10: =IF(ISBLANK($E10),"",INDEX(Sheet1!$A:$J,MATCH(Index_Match!$E10,Sheet1!$A:$A,0),MATCH(Index_Match!L$1,Sheet1!$A$1:$J$1,0))) -> Wright | M10: =IF(ISBLANK($E10),"",INDEX(Sheet1!$A:$J,MATCH(Index_Match!$E10,Sheet1!$A:$A,0),MATCH(Index_Match!M$1,Sheet1!$A$1:$J$1,0))) -> Old
E11: Sofia | F11: =IF(ISBLANK($E11),"",INDEX(Sheet1!$A:$J,MATCH(Index_Match!$E11,Sheet1!$A:$A,0),MATCH(Index_Match!F$1,Sheet1!$A$1:$J$1,0))) -> Female | G11: =IF(ISBLANK($E11),"",INDEX(Sheet1!$A:$J,MATCH(Index_Match!$E11,Sheet1!$A:$A,0),MATCH(Index_Match!G$1,Sheet1!$A$1:$J$1,0))) -> Cook | H11: =IF(ISBLANK($E11),"",INDEX(Sheet1!$A:$J,MATCH(Index_Match!$E11,Sheet1!$A:$A,0),MATCH(Index_Match!H$1,Sheet1!$A$1:$J$1,0))) -> Married | I11: =IF(ISBLANK($E11),"",INDEX(Sheet1!$A:$J,MATCH(Index_Match!$E11,Sheet1!$A:$A,0),MATCH(Index_Match!I$1,Sheet1!$A$1:$J$1,0))) -> 5 | J11: =IF(ISBLANK($E11),"",INDEX(Sheet1!$A:$J,MATCH(Index_Match!$E11,Sheet1!$A:$A,0),MATCH(Index_Match!J$1,Sheet1!$A$1:$J$1,0))) -> Sofia Barnes | K11: =IF(ISBLANK($E11),"",INDEX(Sheet1!$A:$J,MATCH(Index_Match!$E11,Sheet1!$A:$A,0),MATCH(Index_Match!K$1,Sheet1!$A$1:$J$1,0))) -> 5 | L11: =IF(ISBLANK($E11),"",INDEX(Sheet1!$A:$J,MATCH(Index_Match!$E11,Sheet1!$A:$A,0),MATCH(Index_Match!L$1,Sheet1!$A$1:$J$1,0))) -> Barnes | M11: =IF(ISBLANK($E11),"",INDEX(Sheet1!$A:$J,MATCH(Index_Match!$E11,Sheet1!$A:$A,0),MATCH(Index_Match!M$1,Sheet1!$A$1:$J$1,0))) -> Old
E12: Kimberly | F12: =IF(ISBLANK($E12),"",INDEX(Sheet1!$A:$J,MATCH(Index_Match!$E12,Sheet1!$A:$A,0),MATCH(Index_Match!F$1,Sheet1!$A$1:$J$1,0))) -> Female | G12: =IF(ISBLANK($E12),"",INDEX(Sheet1!$A:$J,MATCH(Index_Match!$E12,Sheet1!$A:$A,0),MATCH(Index_Match!G$1,Sheet1!$A$1:$J$1,0))) -> Geologist | H12: =IF(ISBLANK($E12),"",INDEX(Sheet1!$A:$J,MATCH(Index_Match!$E12,Sheet1!$A:$A,0),MATCH(Index_Match!H$1,Sheet1!$A$1:$J$1,0))) -> Single | I12: =IF(ISBLANK($E12),"",INDEX(Sheet1!$A:$J,MATCH(Index_Match!$E12,Sheet1!$A:$A,0),MATCH(Index_Match!I$1,Sheet1!$A$1:$J$1,0))) -> 2 | J12: =IF(ISBLANK($E12),"",INDEX(Sheet1!$A:$J,MATCH(Index_Match!$E12,Sheet1!$A:$A,0),MATCH(Index_Match!J$1,Sheet1!$A$1:$J$1,0))) -> Kimberly Rogers | K12: =IF(ISBLANK($E12),"",INDEX(Sheet1!$A:$J,MATCH(Index_Match!$E12,Sheet1!$A:$A,0),MATCH(Index_Match!K$1,Sheet1!$A$1:$J$1,0))) -> 2 | L12: =IF(ISBLANK($E12),"",INDEX(Sheet1!$A:$J,MATCH(Index_Match!$E12,Sheet1!$A:$A,0),MATCH(Index_Match!L$1,Sheet1!$A$1:$J$1,0))) -> Rogers | M12: =IF(ISBLANK($E12),"",INDEX(Sheet1!$A:$J,MATCH(Index_Match!$E12,Sheet1!$A:$A,0),MATCH(Index_Match!M$1,Sheet1!$A$1:$J$1,0))) -> Old
E13: Emily | F13: =IF(ISBLANK($E13),"",INDEX(Sheet1!$A:$J,MATCH(Index_Match!$E13,Sheet1!$A:$A,0),MATCH(Index_Match!F$1,Sheet1!$A$1:$J$1,0))) -> Female | G13: =IF(ISBLANK($E13),"",INDEX(Sheet1!$A:$J,MATCH(Index_Match!$E13,Sheet1!$A:$A,0),MATCH(Index_Match!G$1,Sheet1!$A$1:$J$1,0))) -> Lawyer | H13: =IF(ISBLANK($E13),"",INDEX(Sheet1!$A:$J,MATCH(Index_Match!$E13,Sheet1!$A:$A,0),MATCH(Index_Match!H$1,Sheet1!$A$1:$J$1,0))) -> Single | I13: =IF(ISBLANK($E13),"",INDEX(Sheet1!$A:$J,MATCH(Index_Match!$E13,Sheet1!$A:$A,0),MATCH(Index_Match!I$1,Sheet1!$A$1:$J$1,0))) -> 0 | J13: =IF(ISBLANK($E13),"",INDEX(Sheet1!$A:$J,MATCH(Index_Match!$E13,Sheet1!$A:$A,0),MATCH(Index_Match!J$1,Sheet1!$A$1:$J$1,0))) -> Emily Chapman | K13: =IF(ISBLANK($E13),"",INDEX(Sheet1!$A:$J,MATCH(Index_Match!$E13,Sheet1!$A:$A,0),MATCH(Index_Match!K$1,Sheet1!$A$1:$J$1,0))) -> 0 | L13: =IF(ISBLANK($E13),"",INDEX(Sheet1!$A:$J,MATCH(Index_Match!$E13,Sheet1!$A:$A,0),MATCH(Index_Match!L$1,Sheet1!$A$1:$J$1,0))) -> Chapman | M13: =IF(ISBLANK($E13),"",INDEX(Sheet1!$A:$J,MATCH(Index_Match!$E13,Sheet1!$A:$A,0),MATCH(Index_Match!M$1,Sheet1!$A$1:$J$1,0))) -> Middle Age
E14: Lucy | F14: =IF(ISBLANK($E14),"",INDEX(Sheet1!$A:$J,MATCH(Index_Match!$E14,Sheet1!$A:$A,0),MATCH(Index_Match!F$1,Sheet1!$A$1:$J$1,0))) -> Female | G14: =IF(ISBLANK($E14),"",INDEX(Sheet1!$A:$J,MATCH(Index_Match!$E14,Sheet1!$A:$A,0),MATCH(Index_Match!G$1,Sheet1!$A$1:$J$1,0))) -> Manager | H14: =IF(ISBLANK($E14),"",INDEX(Sheet1!$A:$J,MATCH(Index_Match!$E14,Sheet1!$A:$A,0),MATCH(Index_Match!H$1,Sheet1!$A$1:$J$1,0))) -> Single | I14: =IF(ISBLANK($E14),"",INDEX(Sheet1!$A:$J,MATCH(Index_Match!$E14,Sheet1!$A:$A,0),MATCH(Index_Match!I$1,Sheet1!$A$1:$J$1,0))) -> 0 | J14: =IF(ISBLANK($E14),"",INDEX(Sheet1!$A:$J,MATCH(Index_Match!$E14,Sheet1!$A:$A,0),MATCH(Index_Match!J$1,Sheet1!$A$1:$J$1,0))) -> Lucy Anderson | K14: =IF(ISBLANK($E14),"",INDEX(Sheet1!$A:$J,MATCH(Index_Match!$E14,Sheet1!$A:$A,0),MATCH(Index_Match!K$1,Sheet1!$A$1:$J$1,0))) -> 0 | L14: =IF(ISBLANK($E14),"",INDEX(Sheet1!$A:$J,MATCH(Index_Match!$E14,Sheet1!$A:$A,0),MATCH(Index_Match!L$1,Sheet1!$A$1:$J$1,0))) -> Anderson | M14: =IF(ISBLANK($E14),"",INDEX(Sheet1!$A:$J,MATCH(Index_Match!$E14,Sheet1!$A:$A,0),MATCH(Index_Match!M$1,Sheet1!$A$1:$J$1,0))) -> Old
... E487: Rosie | F487: =IF(ISBLANK($E487),"",INDEX(Sheet1!$A:$J,MATCH(Index_Match!$E487,Sheet1!$A:$A,0),MATCH(Index_Match!F$1,Sheet1!$A$1:$J$1,0))) -> Female | G487: =IF(ISBLANK($E487),"",INDEX(Sheet1!$A:$J,MATCH(Index_Match!$E487,Sheet1!$A:$A,0),MATCH(Index_Match!G$1,Sheet1!$A$1:$J$1,0))) -> Baker | H487: =IF(ISBLANK($E487),"",INDEX(Sheet1!$A:$J,MATCH(Index_Match!$E487,Sheet1!$A:$A,0),MATCH(Index_Match!H$1,Sheet1!$A$1:$J$1,0))) -> Single | I487: =IF(ISBLANK($E487),"",INDEX(Sheet1!$A:$J,MATCH(Index_Match!$E487,Sheet1!$A:$A,0),MATCH(Index_Match!I$1,Sheet1!$A$1:$J$1,0))) -> 2 | J487: =IF(ISBLANK($E487),"",INDEX(Sheet1!$A:$J,MATCH(Index_Match!$E487,Sheet1!$A:$A,0),MATCH(Index_Match!J$1,Sheet1!$A$1:$J$1,0))) -> Rosie Moore | K487: =IF(ISBLANK($E487),"",INDEX(Sheet1!$A:$J,MATCH(Index_Match!$E487,Sheet1!$A:$A,0),MATCH(Index_Match!K$1,Sheet1!$A$1:$J$1,0))) -> 2 | L487: =IF(ISBLANK($E487),"",INDEX(Sheet1!$A:$J,MATCH(Index_Match!$E487,Sheet1!$A:$A,0),MATCH(Index_Match!L$1,Sheet1!$A$1:$J$1,0))) -> Moore | M487: =IF(ISBLANK($E487),"",INDEX(Sheet1!$A:$J,MATCH(Index_Match!$E487,Sheet1!$A:$A,0),MATCH(Index_Match!M$1,Sheet1!$A$1:$J$1,0))) -> Old
F488: =IF(ISBLANK($E488),"",INDEX(Sheet1!$A:$J,MATCH(Index_Match!$E488,Sheet1!$A:$A,0),MATCH(Index_Match!F$1,Sheet1!$A$1:$J$1,0))) | G488: =IF(ISBLANK($E488),"",INDEX(Sheet1!$A:$J,MATCH(Index_Match!$E488,Sheet1!$A:$A,0),MATCH(Index_Match!G$1,Sheet1!$A$1:$J$1,0))) | H488: =IF(ISBLANK($E488),"",INDEX(Sheet1!$A:$J,MATCH(Index_Match!$E488,Sheet1!$A:$A,0),MATCH(Index_Match!H$1,Sheet1!$A$1:$J$1,0))) | I488: =IF(ISBLANK($E488),"",INDEX(Sheet1!$A:$J,MATCH(Index_Match!$E488,Sheet1!$A:$A,0),MATCH(Index_Match!I$1,Sheet1!$A$1:$J$1,0))) | J488: =IF(ISBLANK($E488),"",INDEX(Sheet1!$A:$J,MATCH(Index_Match!$E488,Sheet1!$A:$A,0),MATCH(Index_Match!J$1,Sheet1!$A$1:$J$1,0))) | K488: =IF(ISBLANK($E488),"",INDEX(Sheet1!$A:$J,MATCH(Index_Match!$E488,Sheet1!$A:$A,0),MATCH(Index_Match!K$1,Sheet1!$A$1:$J$1,0))) | L488: =IF(ISBLANK($E488),"",INDEX(Sheet1!$A:$J,MATCH(Index_Match!$E488,Sheet1!$A:$A,0),MATCH(Index_Match!L$1,Sheet1!$A$1:$J$1,0))) | M488: =IF(ISBLANK($E488),"",INDEX(Sheet1!$A:$J,MATCH(Index_Match!$E488,Sheet1!$A:$A,0),MATCH(Index_Match!M$1,Sheet1!$A$1:$J$1,0)))
F489: =IF(ISBLANK($E489),"",INDEX(Sheet1!$A:$J,MATCH(Index_Match!$E489,Sheet1!$A:$A,0),MATCH(Index_Match!F$1,Sheet1!$A$1:$J$1,0))) | G489: =IF(ISBLANK($E489),"",INDEX(Sheet1!$A:$J,MATCH(Index_Match!$E489,Sheet1!$A:$A,0),MATCH(Index_Match!G$1,Sheet1!$A$1:$J$1,0))) | H489: =IF(ISBLANK($E489),"",INDEX(Sheet1!$A:$J,MATCH(Index_Match!$E489,Sheet1!$A:$A,0),MATCH(Index_Match!H$1,Sheet1!$A$1:$J$1,0))) | I489: =IF(ISBLANK($E489),"",INDEX(Sheet1!$A:$J,MATCH(Index_Match!$E489,Sheet1!$A:$A,0),MATCH(Index_Match!I$1,Sheet1!$A$1:$J$1,0))) | J489: =IF(ISBLANK($E489),"",INDEX(Sheet1!$A:$J,MATCH(Index_Match!$E489,Sheet1!$A:$A,0),MATCH(Index_Match!J$1,Sheet1!$A$1:$J$1,0))) | K489: =IF(ISBLANK($E489),"",INDEX(Sheet1!$A:$J,MATCH(Index_Match!$E489,Sheet1!$A:$A,0),MATCH(Index_Match!K$1,Sheet1!$A$1:$J$1,0))) | L489: =IF(ISBLANK($E489),"",INDEX(Sheet1!$A:$J,MATCH(Index_Match!$E489,Sheet1!$A:$A,0),MATCH(Index_Match!L$1,Sheet1!$A$1:$J$1,0))) | M489: =IF(ISBLANK($E489),"",INDEX(Sheet1!$A:$J,MATCH(Index_Match!$E489,Sheet1!$A:$A,0),MATCH(Index_Match!M$1,Sheet1!$A$1:$J$1,0)))
F490: =IF(ISBLANK($E490),"",INDEX(Sheet1!$A:$J,MATCH(Index_Match!$E490,Sheet1!$A:$A,0),MATCH(Index_Match!F$1,Sheet1!$A$1:$J$1,0))) | G490: =IF(ISBLANK($E490),"",INDEX(Sheet1!$A:$J,MATCH(Index_Match!$E490,Sheet1!$A:$A,0),MATCH(Index_Match!G$1,Sheet1!$A$1:$J$1,0))) | H490: =IF(ISBLANK($E490),"",INDEX(Sheet1!$A:$J,MATCH(Index_Match!$E490,Sheet1!$A:$A,0),MATCH(Index_Match!H$1,Sheet1!$A$1:$J$1,0))) | I490: =IF(ISBLANK($E490),"",INDEX(Sheet1!$A:$J,MATCH(Index_Match!$E490,Sheet1!$A:$A,0),MATCH(Index_Match!I$1,Sheet1!$A$1:$J$1,0))) | J490: =IF(ISBLANK($E490),"",INDEX(Sheet1!$A:$J,MATCH(Index_Match!$E490,Sheet1!$A:$A,0),MATCH(Index_Match!J$1,Sheet1!$A$1:$J$1,0))) | K490: =IF(ISBLANK($E490),"",INDEX(Sheet1!$A:$J,MATCH(Index_Match!$E490,Sheet1!$A:$A,0),MATCH(Index_Match!K$1,Sheet1!$A$1:$J$1,0))) | L490: =IF(ISBLANK($E490),"",INDEX(Sheet1!$A:$J,MATCH(Index_Match!$E490,Sheet1!$A:$A,0),MATCH(Index_Match!L$1,Sheet1!$A$1:$J$1,0))) | M490: =IF(ISBLANK($E490),"",INDEX(Sheet1!$A:$J,MATCH(Index_Match!$E490,Sheet1!$A:$A,0),MATCH(Index_Match!M$1,Sheet1!$A$1:$J$1,0)))
F491: =IF(ISBLANK($E491),"",INDEX(Sheet1!$A:$J,MATCH(Index_Match!$E491,Sheet1!$A:$A,0),MATCH(Index_Match!F$1,Sheet1!$A$1:$J$1,0))) | G491: =IF(ISBLANK($E491),"",INDEX(Sheet1!$A:$J,MATCH(Index_Match!$E491,Sheet1!$A:$A,0),MATCH(Index_Match!G$1,Sheet1!$A$1:$J$1,0))) | H491: =IF(ISBLANK($E491),"",INDEX(Sheet1!$A:$J,MATCH(Index_Match!$E491,Sheet1!$A:$A,0),MATCH(Index_Match!H$1,Sheet1!$A$1:$J$1,0))) | I491: =IF(ISBLANK($E491),"",INDEX(Sheet1!$A:$J,MATCH(Index_Match!$E491,Sheet1!$A:$A,0),MATCH(Index_Match!I$1,Sheet1!$A$1:$J$1,0))) | J491: =IF(ISBLANK($E491),"",INDEX(Sheet1!$A:$J,MATCH(Index_Match!$E491,Sheet1!$A:$A,0),MATCH(Index_Match!J$1,Sheet1!$A$1:$J$1,0))) | K491: =IF(ISBLANK($E491),"",INDEX(Sheet1!$A:$J,MATCH(Index_Match!$E491,Sheet1!$A:$A,0),MATCH(Index_Match!K$1,Sheet1!$A$1:$J$1,0))) | L491: =IF(ISBLANK($E491),"",INDEX(Sheet1!$A:$J,MATCH(Index_Match!$E491,Sheet1!$A:$A,0),MATCH(Index_Match!L$1,Sheet1!$A$1:$J$1,0))) | M491: =IF(ISBLANK($E491),"",INDEX(Sheet1!$A:$J,MATCH(Index_Match!$E491,Sheet1!$A:$A,0),MATCH(Index_Match!M$1,Sheet1!$A$1:$J$1,0)))
F492: =IF(ISBLANK($E492),"",INDEX(Sheet1!$A:$J,MATCH(Index_Match!$E492,Sheet1!$A:$A,0),MATCH(Index_Match!F$1,Sheet1!$A$1:$J$1,0))) | G492: =IF(ISBLANK($E492),"",INDEX(Sheet1!$A:$J,MATCH(Index_Match!$E492,Sheet1!$A:$A,0),MATCH(Index_Match!G$1,Sheet1!$A$1:$J$1,0))) | H492: =IF(ISBLANK($E492),"",INDEX(Sheet1!$A:$J,MATCH(Index_Match!$E492,Sheet1!$A:$A,0),MATCH(Index_Match!H$1,Sheet1!$A$1:$J$1,0))) | I492: =IF(ISBLANK($E492),"",INDEX(Sheet1!$A:$J,MATCH(Index_Match!$E492,Sheet1!$A:$A,0),MATCH(Index_Match!I$1,Sheet1!$A$1:$J$1,0))) | J492: =IF(ISBLANK($E492),"",INDEX(Sheet1!$A:$J,MATCH(Index_Match!$E492,Sheet1!$A:$A,0),MATCH(Index_Match!J$1,Sheet1!$A$1:$J$1,0))) | K492: =IF(ISBLANK($E492),"",INDEX(Sheet1!$A:$J,MATCH(Index_Match!$E492,Sheet1!$A:$A,0),MATCH(Index_Match!K$1,Sheet1!$A$1:$J$1,0))) | L492: =IF(ISBLANK($E492),"",INDEX(Sheet1!$A:$J,MATCH(Index_Match!$E492,Sheet1!$A:$A,0),MATCH(Index_Match!L$1,Sheet1!$A$1:$J$1,0))) | M492: =IF(ISBLANK($E492),"",INDEX(Sheet1!$A:$J,MATCH(Index_Match!$E492,Sheet1!$A:$A,0),MATCH(Index_Match!M$1,Sheet1!$A$1:$J$1,0)))
F493: =IF(ISBLANK($E493),"",INDEX(Sheet1!$A:$J,MATCH(Index_Match!$E493,Sheet1!$A:$A,0),MATCH(Index_Match!F$1,Sheet1!$A$1:$J$1,0))) | G493: =IF(ISBLANK($E493),"",INDEX(Sheet1!$A:$J,MATCH(Index_Match!$E493,Sheet1!$A:$A,0),MATCH(Index_Match!G$1,Sheet1!$A$1:$J$1,0))) | H493: =IF(ISBLANK($E493),"",INDEX(Sheet1!$A:$J,MATCH(Index_Match!$E493,Sheet1!$A:$A,0),MATCH(Index_Match!H$1,Sheet1!$A$1:$J$1,0))) | I493: =IF(ISBLANK($E493),"",INDEX(Sheet1!$A:$J,MATCH(Index_Match!$E493,Sheet1!$A:$A,0),MATCH(Index_Match!I$1,Sheet1!$A$1:$J$1,0))) | J493: =IF(ISBLANK($E493),"",INDEX(Sheet1!$A:$J,MATCH(Index_Match!$E493,Sheet1!$A:$A,0),MATCH(Index_Match!J$1,Sheet1!$A$1:$J$1,0))) | K493: =IF(ISBLANK($E493),"",INDEX(Sheet1!$A:$J,MATCH(Index_Match!$E493,Sheet1!$A:$A,0),MATCH(Index_Match!K$1,Sheet1!$A$1:$J$1,0))) | L493: =IF(ISBLANK($E493),"",INDEX(Sheet1!$A:$J,MATCH(Index_Match!$E493,Sheet1!$A:$A,0),MATCH(Index_Match!L$1,Sheet1!$A$1:$J$1,0))) | M493: =IF(ISBLANK($E493),"",INDEX(Sheet1!$A:$J,MATCH(Index_Match!$E493,Sheet1!$A:$A,0),MATCH(Index_Match!M$1,Sheet1!$A$1:$J$1,0)))
F494: =IF(ISBLANK($E494),"",INDEX(Sheet1!$A:$J,MATCH(Index_Match!$E494,Sheet1!$A:$A,0),MATCH(Index_Match!F$1,Sheet1!$A$1:$J$1,0))) | G494: =IF(ISBLANK($E494),"",INDEX(Sheet1!$A:$J,MATCH(Index_Match!$E494,Sheet1!$A:$A,0),MATCH(Index_Match!G$1,Sheet1!$A$1:$J$1,0))) | H494: =IF(ISBLANK($E494),"",INDEX(Sheet1!$A:$J,MATCH(Index_Match!$E494,Sheet1!$A:$A,0),MATCH(Index_Match!H$1,Sheet1!$A$1:$J$1,0))) | I494: =IF(ISBLANK($E494),"",INDEX(Sheet1!$A:$J,MATCH(Index_Match!$E494,Sheet1!$A:$A,0),MATCH(Index_Match!I$1,Sheet1!$A$1:$J$1,0))) | J494: =IF(ISBLANK($E494),"",INDEX(Sheet1!$A:$J,MATCH(Index_Match!$E494,Sheet1!$A:$A,0),MATCH(Index_Match!J$1,Sheet1!$A$1:$J$1,0))) | K494: =IF(ISBLANK($E494),"",INDEX(Sheet1!$A:$J,MATCH(Index_Match!$E494,Sheet1!$A:$A,0),MATCH(Index_Match!K$1,Sheet1!$A$1:$J$1,0))) | L494: =IF(ISBLANK($E494),"",INDEX(Sheet1!$A:$J,MATCH(Index_Match!$E494,Sheet1!$A:$A,0),MATCH(Index_Match!L$1,Sheet1!$A$1:$J$1,0))) | M494: =IF(ISBLANK($E494),"",INDEX(Sheet1!$A:$J,MATCH(Index_Match!$E494,Sheet1!$A:$A,0),MATCH(Index_Match!M$1,Sheet1!$A$1:$J$1,0)))
F495: =IF(ISBLANK($E495),"",INDEX(Sheet1!$A:$J,MATCH(Index_Match!$E495,Sheet1!$A:$A,0),MATCH(Index_Match!F$1,Sheet1!$A$1:$J$1,0))) | G495: =IF(ISBLANK($E495),"",INDEX(Sheet1!$A:$J,MATCH(Index_Match!$E495,Sheet1!$A:$A,0),MATCH(Index_Match!G$1,Sheet1!$A$1:$J$1,0))) | H495: =IF(ISBLANK($E495),"",INDEX(Sheet1!$A:$J,MATCH(Index_Match!$E495,Sheet1!$A:$A,0),MATCH(Index_Match!H$1,Sheet1!$A$1:$J$1,0))) | I495: =IF(ISBLANK($E495),"",INDEX(Sheet1!$A:$J,MATCH(Index_Match!$E495,Sheet1!$A:$A,0),MATCH(Index_Match!I$1,Sheet1!$A$1:$J$1,0))) | J495: =IF(ISBLANK($E495),"",INDEX(Sheet1!$A:$J,MATCH(Index_Match!$E495,Sheet1!$A:$A,0),MATCH(Index_Match!J$1,Sheet1!$A$1:$J$1,0))) | K495: =IF(ISBLANK($E495),"",INDEX(Sheet1!$A:$J,MATCH(Index_Match!$E495,Sheet1!$A:$A,0),MATCH(Index_Match!K$1,Sheet1!$A$1:$J$1,0))) | L495: =IF(ISBLANK($E495),"",INDEX(Sheet1!$A:$J,MATCH(Index_Match!$E495,Sheet1!$A:$A,0),MATCH(Index_Match!L$1,Sheet1!$A$1:$J$1,0))) | M495: =IF(ISBLANK($E495),"",INDEX(Sheet1!$A:$J,MATCH(Index_Match!$E495,Sheet1!$A:$A,0),MATCH(Index_Match!M$1,Sheet1!$A$1:$J$1,0)))
F496: =IF(ISBLANK($E496),"",INDEX(Sheet1!$A:$J,MATCH(Index_Match!$E496,Sheet1!$A:$A,0),MATCH(Index_Match!F$1,Sheet1!$A$1:$J$1,0))) | G496: =IF(ISBLANK($E496),"",INDEX(Sheet1!$A:$J,MATCH(Index_Match!$E496,Sheet1!$A:$A,0),MATCH(Index_Match!G$1,Sheet1!$A$1:$J$1,0))) | H496: =IF(ISBLANK($E496),"",INDEX(Sheet1!$A:$J,MATCH(Index_Match!$E496,Sheet1!$A:$A,0),MATCH(Index_Match!H$1,Sheet1!$A$1:$J$1,0))) | I496: =IF(ISBLANK($E496),"",INDEX(Sheet1!$A:$J,MATCH(Index_Match!$E496,Sheet1!$A:$A,0),MATCH(Index_Match!I$1,Sheet1!$A$1:$J$1,0))) | J496: =IF(ISBLANK($E496),"",INDEX(Sheet1!$A:$J,MATCH(Index_Match!$E496,Sheet1!$A:$A,0),MATCH(Index_Match!J$1,Sheet1!$A$1:$J$1,0))) | K496: =IF(ISBLANK($E496),"",INDEX(Sheet1!$A:$J,MATCH(Index_Match!$E496,Sheet1!$A:$A,0),MATCH(Index_Match!K$1,Sheet1!$A$1:$J$1,0))) | L496: =IF(ISBLANK($E496),"",INDEX(Sheet1!$A:$J,MATCH(Index_Match!$E496,Sheet1!$A:$A,0),MATCH(Index_Match!L$1,Sheet1!$A$1:$J$1,0))) | M496: =IF(ISBLANK($E496),"",INDEX(Sheet1!$A:$J,MATCH(Index_Match!$E496,Sheet1!$A:$A,0),MATCH(Index_Match!M$1,Sheet1!$A$1:$J$1,0)))
F497: =IF(ISBLANK($E497),"",INDEX(Sheet1!$A:$J,MATCH(Index_Match!$E497,Sheet1!$A:$A,0),MATCH(Index_Match!F$1,Sheet1!$A$1:$J$1,0))) | G497: =IF(ISBLANK($E497),"",INDEX(Sheet1!$A:$J,MATCH(Index_Match!$E497,Sheet1!$A:$A,0),MATCH(Index_Match!G$1,Sheet1!$A$1:$J$1,0))) | H497: =IF(ISBLANK($E497),"",INDEX(Sheet1!$A:$J,MATCH(Index_Match!$E497,Sheet1!$A:$A,0),MATCH(Index_Match!H$1,Sheet1!$A$1:$J$1,0))) | I497: =IF(ISBLANK($E497),"",INDEX(Sheet1!$A:$J,MATCH(Index_Match!$E497,Sheet1!$A:$A,0),MATCH(Index_Match!I$1,Sheet1!$A$1:$J$1,0))) | J497: =IF(ISBLANK($E497),"",INDEX(Sheet1!$A:$J,MATCH(Index_Match!$E497,Sheet1!$A:$A,0),MATCH(Index_Match!J$1,Sheet1!$A$1:$J$1,0))) | K497: =IF(ISBLANK($E497),"",INDEX(Sheet1!$A:$J,MATCH(Index_Match!$E497,Sheet1!$A:$A,0),MATCH(Index_Match!K$1,Sheet1!$A$1:$J$1,0))) | L497: =IF(ISBLANK($E497),"",INDEX(Sheet1!$A:$J,MATCH(Index_Match!$E497,Sheet1!$A:$A,0),MATCH(Index_Match!L$1,Sheet1!$A$1:$J$1,0))) | M497: =IF(ISBLANK($E497),"",INDEX(Sheet1!$A:$J,MATCH(Index_Match!$E497,Sheet1!$A:$A,0),MATCH(Index_Match!M$1,Sheet1!$A$1:$J$1,0)))
F498: =IF(ISBLANK($E498),"",INDEX(Sheet1!$A:$J,MATCH(Index_Match!$E498,Sheet1!$A:$A,0),MATCH(Index_Match!F$1,Sheet1!$A$1:$J$1,0))) | G498: =IF(ISBLANK($E498),"",INDEX(Sheet1!$A:$J,MATCH(Index_Match!$E498,Sheet1!$A:$A,0),MATCH(Index_Match!G$1,Sheet1!$A$1:$J$1,0))) | H498: =IF(ISBLANK($E498),"",INDEX(Sheet1!$A:$J,MATCH(Index_Match!$E498,Sheet1!$A:$A,0),MATCH(Index_Match!H$1,Sheet1!$A$1:$J$1,0))) | I498: =IF(ISBLANK($E498),"",INDEX(Sheet1!$A:$J,MATCH(Index_Match!$E498,Sheet1!$A:$A,0),MATCH(Index_Match!I$1,Sheet1!$A$1:$J$1,0))) | J498: =IF(ISBLANK($E498),"",INDEX(Sheet1!$A:$J,MATCH(Index_Match!$E498,Sheet1!$A:$A,0),MATCH(Index_Match!J$1,Sheet1!$A$1:$J$1,0))) | K498: =IF(ISBLANK($E498),"",INDEX(Sheet1!$A:$J,MATCH(Index_Match!$E498,Sheet1!$A:$A,0),MATCH(Index_Match!K$1,Sheet1!$A$1:$J$1,0))) | L498: =IF(ISBLANK($E498),"",INDEX(Sheet1!$A:$J,MATCH(Index_Match!$E498,Sheet1!$A:$A,0),MATCH(Index_Match!L$1,Sheet1!$A$1:$J$1,0))) | M498: =IF(ISBLANK($E498),"",INDEX(Sheet1!$A:$J,MATCH(Index_Match!$E498,Sheet1!$A:$A,0),MATCH(Index_Match!M$1,Sheet1!$A$1:$J$1,0)))
F499: =IF(ISBLANK($E499),"",INDEX(Sheet1!$A:$J,MATCH(Index_Match!$E499,Sheet1!$A:$A,0),MATCH(Index_Match!F$1,Sheet1!$A$1:$J$1,0))) | G499: =IF(ISBLANK($E499),"",INDEX(Sheet1!$A:$J,MATCH(Index_Match!$E499,Sheet1!$A:$A,0),MATCH(Index_Match!G$1,Sheet1!$A$1:$J$1,0))) | H499: =IF(ISBLANK($E499),"",INDEX(Sheet1!$A:$J,MATCH(Index_Match!$E499,Sheet1!$A:$A,0),MATCH(Index_Match!H$1,Sheet1!$A$1:$J$1,0))) | I499: =IF(ISBLANK($E499),"",INDEX(Sheet1!$A:$J,MATCH(Index_Match!$E499,Sheet1!$A:$A,0),MATCH(Index_Match!I$1,Sheet1!$A$1:$J$1,0))) | J499: =IF(ISBLANK($E499),"",INDEX(Sheet1!$A:$J,MATCH(Index_Match!$E499,Sheet1!$A:$A,0),MATCH(Index_Match!J$1,Sheet1!$A$1:$J$1,0))) | K499: =IF(ISBLANK($E499),"",INDEX(Sheet1!$A:$J,MATCH(Index_Match!$E499,Sheet1!$A:$A,0),MATCH(Index_Match!K$1,Sheet1!$A$1:$J$1,0))) | L499: =IF(ISBLANK($E499),"",INDEX(Sheet1!$A:$J,MATCH(Index_Match!$E499,Sheet1!$A:$A,0),MATCH(Index_Match!L$1,Sheet1!$A$1:$J$1,0))) | M499: =IF(ISBLANK($E499),"",INDEX(Sheet1!$A:$J,MATCH(Index_Match!$E499,Sheet1!$A:$A,0),MATCH(Index_Match!M$1,Sheet1!$A$1:$J$1,0)))
... F515: =IF(ISBLANK($E515),"",INDEX(Sheet1!$A:$J,MATCH(Index_Match!$E515,Sheet1!$A:$A,0),MATCH(Index_Match!F$1,Sheet1!$A$1:$J$1,0))) | G515: =IF(ISBLANK($E515),"",INDEX(Sheet1!$A:$J,MATCH(Index_Match!$E515,Sheet1!$A:$A,0),MATCH(Index_Match!G$1,Sheet1!$A$1:$J$1,0))) | H515: =IF(ISBLANK($E515),"",INDEX(Sheet1!$A:$J,MATCH(Index_Match!$E515,Sheet1!$A:$A,0),MATCH(Index_Match!H$1,Sheet1!$A$1:$J$1,0))) | I515: =IF(ISBLANK($E515),"",INDEX(Sheet1!$A:$J,MATCH(Index_Match!$E515,Sheet1!$A:$A,0),MATCH(Index_Match!I$1,Sheet1!$A$1:$J$1,0))) | J515: =IF(ISBLANK($E515),"",INDEX(Sheet1!$A:$J,MATCH(Index_Match!$E515,Sheet1!$A:$A,0),MATCH(Index_Match!J$1,Sheet1!$A$1:$J$1,0))) | K515: =IF(ISBLANK($E515),"",INDEX(Sheet1!$A:$J,MATCH(Index_Match!$E515,Sheet1!$A:$A,0),MATCH(Index_Match!K$1,Sheet1!$A$1:$J$1,0))) | L515: =IF(ISBLANK($E515),"",INDEX(Sheet1!$A:$J,MATCH(Index_Match!$E515,Sheet1!$A:$A,0),MATCH(Index_Match!L$1,Sheet1!$A$1:$J$1,0))) | M515: =IF(ISBLANK($E515),"",INDEX(Sheet1!$A:$J,MATCH(Index_Match!$E515,Sheet1!$A:$A,0),MATCH(Index_Match!M$1,Sheet1!$A$1:$J$1,0)))

Sheet Sheet1
A1: First Name | B1: Last Name | C1: Full Name | D1: Gender | E1: Age | F1: Age Bracket | G1: Occupation | H1: Salary | I1: Marital Status | J1: No. of Children | M1: Male | N1: single | O1: Middle age
A2: Jacob | B2: Robinson | C2: Jacob Robinson | D2: Male | E2: 58 | F2: Old | G2: Lawyer | H2: 6779 | I2: Married | J2: 2 | L2: Sumifs | M2: =SUMIFS(J:J,D:D,M1,I:I,N1,F:F,O1) -> 255
A3: Grace | B3: Taylor | C3: Grace Taylor | D3: Female | E3: 36 | F3: Middle Age | G3: Insurer | H3: 4466 | I3: Married | J3: 1
A4: Charlie | B4: Wilson | C4: Charlie Wilson | D4: Male | E4: 58 | F4: Old | G4: Aeroplane Pilot | H4: 5786 | I4: Single | J4: 0
A5: Vanessa | B5: Farrell | C5: Vanessa Farrell | D5: Female | E5: 23 | F5: Young | G5: Lawyer | H5: 3403 | I5: Married | J5: 2 | L5: Countifs | M5: =COUNTIFS(D:D,M1,I:I,N1,F:F,O1) -> 110
A6: Fenton | B6: Harrison | C6: Fenton Harrison | D6: Male | E6: 21 | F6: Young | G6: Architect | H6: 693 | I6: Married | J6: 0
A7: Lucas | B7: Brooks | C7: Lucas Brooks | D7: Male | E7: 38 | F7: Middle Age | G7: Auditor | H7: 3029 | I7: Single | J7: 1
A8: Belinda | B8: Spencer | C8: Belinda Spencer | D8: Female | E8: 24 | F8: Young | G8: Dancer | H8: 8927 | I8: Married | J8: 5 | L8: Unique | M8: Sumif
A9: Ashton | B9: Farrell | C9: Ashton Farrell | D9: Male | E9: 30 | F9: Young | G9: Cook | H9: 916 | I9: Married | J9: 1 | L9: {=_xlfn.UNIQUE(D2:D1001)} -> Male | M9: =SUMIF(D:D,L9,J:J) -> 1263
A10: Kellan | B10: Williams | C10: Kellan Williams | D10: Male | E10: 38 | F10: Middle Age | G10: Police Officer | H10: 8337 | I10: Married | J10: 4 | L10: Female | M10: =SUMIF(D:D,L10,J:J) -> 1184
A11: Tyler | B11: Davis | C11: Tyler Davis | D11: Male | E11: 60 | F11: Old | G11: Dancer | H11: 2705 | I11: Married | J11: 1
A12: Alina | B12: Russell | C12: Alina Russell | D12: Female | E12: 51 | F12: Old | G12: Engineer | H12: 8411 | I12: Single | J12: 0
A13: Tiana | B13: Wright | C13: Tiana Wright | D13: Female | E13: 59 | F13: Old | G13: Composer | H13: 8087 | I13: Single | J13: 4
A14: Kimberly | B14: Rogers | C14: Kimberly Rogers | D14: Female | E14: 54 | F14: Old | G14: Geologist | H14: 7929 | I14: Single | J14: 2 | M14: ramesh | N14: 12 | O14: 12 | P14: 13 | Q14: 14
A15: Amelia | B15: Craig | C15: Amelia Craig | D15: Female | E15: 55 | F15: Old | G15: Scientist | H15: 9278 | I15: Single | J15: 2 | M15: suresh | N15: 11 | O15: 56 | P15: 12 | Q15: 24
A16: Connie | B16: Martin | C16: Connie Martin | D16: Female | E16: 56 | F16: Old | G16: Economist | H16: 7868 | I16: Single | J16: 1 | M16: ram | N16: 1 | O16: 45 | P16: 61 | Q16: 23
A17: Edgar | B17: Thomas | C17: Edgar Thomas | D17: Male | E17: 42 | F17: Middle Age | G17: Driver | H17: 2264 | I17: Married | J17: 3
A18: Steven | B18: Johnson | C18: Steven Johnson | D18: Male | E18: 48 | F18: Middle Age | G18: Auditor | H18: 2533 | I18: Single | J18: 5 | M18: ram | N18: {=SUM(VLOOKUP(M18,M14:Q16,{2,3,4,5},0))} -> 130
A19: Charlie | B19: Hall | C19: Charlie Hall | D19: Male | E19: 47 | F19: Middle Age | G19: Mathematician | H19: 1378 | I19: Single | J19: 4
A20: Richard | B20: Richards | C20: Richard Richards | D20: Male | E20: 56 | F20: Old | G20: Engineer | H20: 6229 | I20: Single | J20: 2
A21: Alan | B21: Allen | C21: Alan Allen | D21: Male | E21: 57 | F21: Old | G21: Singer | H21: 5461 | I21: Single | J21: 2
A22: Nicholas | B22: Owens | C22: Nicholas Owens | D22: Male | E22: 47 | F22: Middle Age | G22: Fine Artist | H22: 931 | I22: Married | J22: 3
A23: Tiana | B23: Farrell | C23: Tiana Farrell | D23: Female | E23: 43 | F23: Middle Age | G23: Programmer | H23: 5120 | I23: Single | J23: 0
A24: Sawyer | B24: Carter | C24: Sawyer Carter | D24: Male | E24: 26 | F24: Young | G24: Medic | H24: 9039 | I24: Married | J24: 4
A25: Lyndon | B25: Parker | C25: Lyndon Parker | D25: Male | E25: 45 | F25: Middle Age | G25: Programmer | H25: 4813 | I25: Married | J25: 1
A26: Sofia | B26: Barnes | C26: Sofia Barnes | D26: Female | E26: 58 | F26: Old | G26: Cook | H26: 4856 | I26: Married | J26: 5
A27: Walter | B27: Allen | C27: Walter Allen | D27: Male | E27: 24 | F27: Young | G27: Police Officer | H27: 4406 | I27: Married | J27: 5
A28: Kimberly | B28: Payne | C28: Kimberly Payne | D28: Female | E28: 31 | F28: Middle Age | G28: Driver | H28: 2213 | I28: Married | J28: 3
A29: Emily | B29: Chapman | C29: Emily Chapman | D29: Female | E29: 46 | F29: Middle Age | G29: Lawyer | H29: 6890 | I29: Single | J29: 0
A30: Lucy | B30: Anderson | C30: Lucy Anderson | D30: Female | E30: 58 | F30: Old | G30: Manager | H30: 4702 | I30: Single | J30: 0
... A1001: Dexter | B1001: Williams | C1001: Dexter Williams | D1001: Male | E1001: 58 | F1001: Old | G1001: Insurer | H1001: 7075 | I1001: Single | J1001: 0

Sheet FILTER AND OR
B1: Gender | D1: First Name | E1: Last Name | F1: Full Name | G1: Gender | H1: Age | I1: Age Bracket | J1: Occupation | K1: Salary | L1: Marital Status | M1: No. of Children
